{"errorMessage": "An error occurred (ValidationException) when calling the GetResourceOauth2Token operation: You must register and use at least one ResourceOauth2ReturnUrl on your workload identity to use this flow", "errorType": "ValidationException", "requestId": "15b1bbf4-8f26-497c-b508-d121b4bb414b", "stackTrace": ["  File \"/var/task/operations.py\", line 284, in lambda_handler\n    result = asyncio.run(\n", "  File \"/var/lang/lib/python3.12/asyncio/runners.py\", line 195, in run\n    return runner.run(main)\n", "  File \"/var/lang/lib/python3.12/asyncio/runners.py\", line 118, in run\n    return self._loop.run_until_complete(task)\n", "  File \"/var/lang/lib/python3.12/asyncio/base_events.py\", line 691, in run_until_complete\n    return future.result()\n", "  File \"/var/task/bedrock_agentcore/identity/auth.py\", line 69, in async_wrapper\n    token = await _get_token()\n", "  File \"/var/task/bedrock_agentcore/identity/auth.py\", line 55, in _get_token\n    return await client.get_token(\n", "  File \"/var/task/bedrock_agentcore/services/identity.py\", line 210, in get_token\n    response = self.dp_client.get_resource_oauth2_token(**req)\n", "  File \"/var/task/botocore/client.py\", line 602, in _api_call\n    return self._make_api_call(operation_name, kwargs)\n", "  File \"/var/task/botocore/context.py\", line 123, in wrapper\n    return func(*args, **kwargs)\n", "  File \"/var/task/botocore/client.py\", line 1078, in _make_api_call\n    raise error_class(parsed_response, operation_name)\n"]}